Workbook

Sheet GLOSARIO 

Sheet ESTACIÓN
A1: SERVICIO NACIONAL DE GUARDACOSTAS Ministerio Seguridad Pública REGISTRO DE RESULTADOS OPERATIVOS , AÑO 2026
A3: ESTACIÓN DE GUARDACOSTAS: | B3: MURCIELAGO
A4: UNIDAD:
A5: SEMANA: | B5: Fecha inicio | D5: 46113 | F5: al | G5: Fecha final | I5: =IF(D5="","",D5+7) -> 46120
A6: CIERRE DE ORDEN | B6: 12
A7: NÚMERO DE REPORTE DE VIAJE:
A8: ITEM/DIA | B8: =IF($D$5="","",$D$5+0) -> 46113 | C8: =IF($D$5="","",$D$5+1) -> 46114 | D8: =IF($D$5="","",$D$5+2) -> 46115 | E8: =IF($D$5="","",$D$5+3) -> 46116 | F8: =IF($D$5="","",$D$5+4) -> 46117 | G8: =IF($D$5="","",$D$5+5) -> 46118 | H8: =IF($D$5="","",$D$5+6) -> 46119 | I8: =IF($D$5="","",$D$5+7) -> 46120 | J8: TOTAL
A9: 1. RECURSOS INVERTIDOS
A10: a. Millas recorridas por embarcación durante el patrullaje | J10: =SUM(B10:I10) -> 0 | U10: =COUNT(J10:J277) -> 250 | V10: =COUNTIF(J10:J277,"0") -> 250
A11: b. Kilómetros recorridos por el vehículo durante el patrullaje | J11: =SUM(B11:I11) -> 0
A12: c. Kilómetros recorridos caminando durante el patrullaje | J12: =SUM(B12:I12) -> 0
A13: d. Horas navegadas | J13: =SUM(B13:I13) -> 0
A14: e. Horas motor | J14: =SUM(B14:I14) -> 0
A15: f. Litros de gasolina abastecidos previos al patrullaje | J15: =SUM(B15:I15) -> 0
A16: g. Litros de gasolina consumidos durante el patrullaje | J16: =SUM(B16:I16) -> 0
A17: h. Litros de diesel abastecido previos al patrullaje | J17: =SUM(B17:I17) -> 0
A18: i. Litros de diesel consumidos durante el patrullaje | J18: =SUM(B18:I18) -> 0
A19: j. Consumo de aceite de mezcla durante patrullaje (cuartos) | J19: =SUM(B19:I19) -> 0
A20: k. Consumo de aceite de motor (galones) | J20: =SUM(B20:I20) -> 0
A21: 2. HORAS LABORADAS
A22: 2.1. HORAS OPERATIVAS
A23: a. Total de Horas Opertativas en patrullajes o puesto fijos
A24: a.1. Horas operativas en patrullajes y puestos fijos | J24: =SUM(B24:I24) -> 0
A25: 2.2. HORAS EN GESTION OPERATIVA DE APOYO
A26: b. Total de horas en apoyo logístico | B26: =SUM(B27:B34) -> 0 | C26: =SUM(C27:C34) -> 0 | D26: =SUM(D27:D34) -> 0 | E26: =SUM(E27:E34) -> 0 | F26: =SUM(F27:F34) -> 0 | G26: =SUM(G27:G34) -> 0 | H26: =SUM(H27:H34) -> 0 | I26: =SUM(I27:I34) -> 0 | J26: =SUM(B26:I26) -> 0
A27: b.1. Horas planificación, dirección, coordinación, supervisión. | J27: =SUM(B27:I27) -> 0
A28: b.2. Horas operativas en oficialía de guardia y vigilancia perimetral | J28: =SUM(B28:I28) -> 0
A29: b.3. Horas en procesos judiciales o administrativos | J29: =SUM(B29:I29) -> 0
A30: b.4. Horas en elaboración de documentos oficiales | J30: =SUM(B30:I30) -> 0
A31: b.5. Horas en mantenimiento de activos utilizados para patrullajes. | J31: =SUM(B31:I31) -> 0
A32: b.6. Horas en ornato, aseo de la Estación y/o Puesto, horas en mantenimiento de activos no utilizados para patrullaje, labores de preparación de alimentos, carga, descarga, transbordo de global y suministros (logística relacionada a alimentación y suministros en general) | J32: =SUM(B32:I32) -> 0
A33: b.7. Horas en reuniones | J33: =SUM(B33:I33) -> 0
A34: b.8 Horas Acondicionamiento Fisico | J34: =SUM(B34:I34) -> 0
A35: 2.3 HORAS EN PROYECCIÓN SOCIAL Y CAPACITACIÓN
A36: c. Total de horas proyección social y formación | B36: =SUM(B37:B39) -> 0 | C36: =SUM(C37:C39) -> 0 | D36: =SUM(D37:D39) -> 0 | E36: =SUM(E37:E39) -> 0 | F36: =SUM(F37:F39) -> 0 | G36: =SUM(G37:G39) -> 0 | H36: =SUM(H37:H39) -> 0 | I36: =SUM(I37:I39) -> 0 | J36: =SUM(B36:I36) -> 0
A37: c.1. Horas en charlas, talleres, capacitaciones impartidas | J37: =SUM(B37:I37) -> 0
A38: c.2. Horas en charlas, talleres, capacitaciones recibidas | J38: =SUM(B38:I38) -> 0
A39: c.3. Horas en actividades comunitarias | J39: =SUM(B39:I39) -> 0
A40: 2.4 OTRAS HORAS
A41: d.Total de Horas no operativas en servicio dentro de la base o puesto (stand by: espera por alerta de narcotráfico, espera por logística, espera por alguna situación ). | J41: =SUM(B41:I41) -> 0
...

Sheet SNG-08
A1: SERVICIO NACIONAL DE GUARDACOSTAS Ministerio Seguridad Pública REGISTRO DE RESULTADOS OPERATIVOS , AÑO 2026
A3: ESTACIÓN DE GUARDACOSTAS: | B3: =IF(ESTACIÓN!B3="","",ESTACIÓN!B3) -> MURCIELAGO
A4: UNIDAD: | B4: =IF(ESTACIÓN!B4="","",ESTACIÓN!B4)
A5: SEMANA: | B5: =IF(ESTACIÓN!D5="","",ESTACIÓN!D5) -> 46113 | F5: al | G5: =IF(ESTACIÓN!I5="","",ESTACIÓN!I5) -> 46120
A6: CIERRE DE ORDEN | B6: =IF(ESTACIÓN!B6="","",ESTACIÓN!B6) -> 12
A7: NÚMERO DE REPORTE DE VIAJE:
A8: ITEM/DIA | B8: =ESTACIÓN!$B$8 -> 46113 | C8: =ESTACIÓN!$C$8 -> 46114 | D8: =ESTACIÓN!$D$8 -> 46115 | E8: =ESTACIÓN!$E$8 -> 46116 | F8: =ESTACIÓN!$F$8 -> 46117 | G8: =ESTACIÓN!$G$8 -> 46118 | H8: =ESTACIÓN!$H$8 -> 46119 | I8: =ESTACIÓN!$I$8 -> 46120 | J8: TOTAL
A9: 1. RECURSOS INVERTIDOS
A10: a. Millas recorridas por embarcación durante el patrullaje | J10: =SUM(B10:I10) -> 0 | U10: =COUNT(J10:J277) -> 250 | V10: =COUNTIF(J10:J277,"0") -> 250
A11: b. Kilómetros recorridos por el vehículo durante el patrullaje | J11: =SUM(B11:I11) -> 0
A12: c. Kilómetros recorridos caminando durante el patrullaje | J12: =SUM(B12:I12) -> 0
A13: d. Horas navegadas | J13: =SUM(B13:I13) -> 0
A14: e. Horas motor | J14: =SUM(B14:I14) -> 0
A15: f. Litros de gasolina abastecidos previos al patrullaje | J15: =SUM(B15:I15) -> 0
A16: g. Litros de gasolina consumidos durante el patrullaje | J16: =SUM(B16:I16) -> 0
A17: h. Litros de diesel abastecido previos al patrullaje | J17: =SUM(B17:I17) -> 0
A18: i. Litros de diesel consumidos durante el patrullaje | J18: =SUM(B18:I18) -> 0
A19: j. Consumo de aceite de mezcla durante patrullaje (cuartos) | J19: =SUM(B19:I19) -> 0
A20: k. Consumo de aceite de motor (galones) | J20: =SUM(B20:I20) -> 0
A21: 2. HORAS LABORADAS
A22: 2.1. HORAS OPERATIVAS
A23: a. Total de Horas Opertativas en patrullajes o puesto fijos
A24: a.1. Horas operativas en patrullajes y puestos fijos | J24: =SUM(B24:I24) -> 0
A25: 2.2. HORAS EN GESTION OPERATIVA DE APOYO
A26: b. Total de horas en apoyo logístico | B26: =SUM(B27:B34) -> 0 | C26: =SUM(C27:C34) -> 0 | D26: =SUM(D27:D34) -> 0 | E26: =SUM(E27:E34) -> 0 | F26: =SUM(F27:F34) -> 0 | G26: =SUM(G27:G34) -> 0 | H26: =SUM(H27:H34) -> 0 | I26: =SUM(I27:I34) -> 0 | J26: =SUM(B26:I26) -> 0
A27: b.1. Horas planificación, dirección, coordinación, supervisión. | J27: =SUM(B27:I27) -> 0
A28: b.2. Horas operativas en oficialía de guardia y vigilancia perimetral | J28: =SUM(B28:I28) -> 0
A29: b.3. Horas en procesos judiciales o administrativos | J29: =SUM(B29:I29) -> 0
A30: b.4. Horas en elaboración de documentos oficiales | J30: =SUM(B30:I30) -> 0
A31: b.5. Horas en mantenimiento de activos utilizados para patrullajes. | J31: =SUM(B31:I31) -> 0
A32: b.6. Horas en ornato, aseo de la Estación y/o Puesto, horas en mantenimiento de activos no utilizados para patrullaje, labores de preparación de alimentos, carga, descarga, transbordo de global y suministros (logística relacionada a alimentación y suministros en general) | J32: =SUM(B32:I32) -> 0
A33: b.7. Horas en reuniones | J33: =SUM(B33:I33) -> 0
A34: b.8 Horas Acondicionamiento Fisico | J34: =SUM(B34:I34) -> 0
A35: 2.3 HORAS EN PROYECCIÓN SOCIAL Y CAPACITACIÓN
A36: c. Total de horas proyección social y formación | B36: =SUM(B37:B39) -> 0 | C36: =SUM(C37:C39) -> 0 | D36: =SUM(D37:D39) -> 0 | E36: =SUM(E37:E39) -> 0 | F36: =SUM(F37:F39) -> 0 | G36: =SUM(G37:G39) -> 0 | H36: =SUM(H37:H39) -> 0 | I36: =SUM(I37:I39) -> 0 | J36: =SUM(B36:I36) -> 0
A37: c.1. Horas en charlas, talleres, capacitaciones impartidas | J37: =SUM(B37:I37) -> 0
A38: c.2. Horas en charlas, talleres, capacitaciones recibidas | J38: =SUM(B38:I38) -> 0
A39: c.3. Horas en actividades comunitarias | J39: =SUM(B39:I39) -> 0
A40: 2.4 OTRAS HORAS
A41: d.Total de Horas no operativas en servicio dentro de la base o puesto (stand by: espera por alerta de narcotráfico, espera por logística, espera por alguna situación ). | J41: =SUM(B41:I41) -> 0
...

Sheet SNG-16
A1: SERVICIO NACIONAL DE GUARDACOSTAS Ministerio Seguridad Pública REGISTRO DE RESULTADOS OPERATIVOS , AÑO 2026
A3: ESTACIÓN DE GUARDACOSTAS: | B3: =IF(ESTACIÓN!B3="","",ESTACIÓN!B3) -> MURCIELAGO
A4: UNIDAD: | B4: =IF(ESTACIÓN!B4="","",ESTACIÓN!B4)
A5: SEMANA: | B5: =IF(ESTACIÓN!D5="","",ESTACIÓN!D5) -> 46113 | F5: al | G5: =IF(ESTACIÓN!I5="","",ESTACIÓN!I5) -> 46120
A6: CIERRE DE ORDEN | B6: =IF(ESTACIÓN!B6="","",ESTACIÓN!B6) -> 12
A7: NÚMERO DE REPORTE DE VIAJE:
A8: ITEM/DIA | B8: =ESTACIÓN!$B$8 -> 46113 | C8: =ESTACIÓN!$C$8 -> 46114 | D8: =ESTACIÓN!$D$8 -> 46115 | E8: =ESTACIÓN!$E$8 -> 46116 | F8: =ESTACIÓN!$F$8 -> 46117 | G8: =ESTACIÓN!$G$8 -> 46118 | H8: =ESTACIÓN!$H$8 -> 46119 | I8: =ESTACIÓN!$I$8 -> 46120 | J8: TOTAL
A9: 1. RECURSOS INVERTIDOS
A10: a. Millas recorridas por embarcación durante el patrullaje | J10: =SUM(B10:I10) -> 0 | U10: =COUNT(J10:J277) -> 250 | V10: =COUNTIF(J10:J277,"0") -> 250
A11: b. Kilómetros recorridos por el vehículo durante el patrullaje | J11: =SUM(B11:I11) -> 0
A12: c. Kilómetros recorridos caminando durante el patrullaje | J12: =SUM(B12:I12) -> 0
A13: d. Horas navegadas | J13: =SUM(B13:I13) -> 0
A14: e. Horas motor | J14: =SUM(B14:I14) -> 0
A15: f. Litros de gasolina abastecidos previos al patrullaje | J15: =SUM(B15:I15) -> 0
A16: g. Litros de gasolina consumidos durante el patrullaje | J16: =SUM(B16:I16) -> 0
A17: h. Litros de diesel abastecido previos al patrullaje | J17: =SUM(B17:I17) -> 0
A18: i. Litros de diesel consumidos durante el patrullaje | J18: =SUM(B18:I18) -> 0
A19: j. Consumo de aceite de mezcla durante patrullaje (cuartos) | J19: =SUM(B19:I19) -> 0
A20: k. Consumo de aceite de motor (galones) | J20: =SUM(B20:I20) -> 0
A21: 2. HORAS LABORADAS
A22: 2.1. HORAS OPERATIVAS
A23: a. Total de Horas Opertativas en patrullajes o puesto fijos
A24: a.1. Horas operativas en patrullajes y puestos fijos | J24: =SUM(B24:I24) -> 0
A25: 2.2. HORAS EN GESTION OPERATIVA DE APOYO
A26: b. Total de horas en apoyo logístico | B26: =SUM(B27:B34) -> 0 | C26: =SUM(C27:C34) -> 0 | D26: =SUM(D27:D34) -> 0 | E26: =SUM(E27:E34) -> 0 | F26: =SUM(F27:F34) -> 0 | G26: =SUM(G27:G34) -> 0 | H26: =SUM(H27:H34) -> 0 | I26: =SUM(I27:I34) -> 0 | J26: =SUM(B26:I26) -> 0
A27: b.1. Horas planificación, dirección, coordinación, supervisión. | J27: =SUM(B27:I27) -> 0
A28: b.2. Horas operativas en oficialía de guardia y vigilancia perimetral | J28: =SUM(B28:I28) -> 0
A29: b.3. Horas en procesos judiciales o administrativos | J29: =SUM(B29:I29) -> 0
A30: b.4. Horas en elaboración de documentos oficiales | J30: =SUM(B30:I30) -> 0
A31: b.5. Horas en mantenimiento de activos utilizados para patrullajes. | J31: =SUM(B31:I31) -> 0
A32: b.6. Horas en ornato, aseo de la Estación y/o Puesto, horas en mantenimiento de activos no utilizados para patrullaje, labores de preparación de alimentos, carga, descarga, transbordo de global y suministros (logística relacionada a alimentación y suministros en general) | J32: =SUM(B32:I32) -> 0
A33: b.7. Horas en reuniones | J33: =SUM(B33:I33) -> 0
A34: b.8 Horas Acondicionamiento Fisico | J34: =SUM(B34:I34) -> 0
A35: 2.3 HORAS EN PROYECCIÓN SOCIAL Y CAPACITACIÓN
A36: c. Total de horas proyección social y formación | B36: =SUM(B37:B39) -> 0 | C36: =SUM(C37:C39) -> 0 | D36: =SUM(D37:D39) -> 0 | E36: =SUM(E37:E39) -> 0 | F36: =SUM(F37:F39) -> 0 | G36: =SUM(G37:G39) -> 0 | H36: =SUM(H37:H39) -> 0 | I36: =SUM(I37:I39) -> 0 | J36: =SUM(B36:I36) -> 0
A37: c.1. Horas en charlas, talleres, capacitaciones impartidas | J37: =SUM(B37:I37) -> 0
A38: c.2. Horas en charlas, talleres, capacitaciones recibidas | J38: =SUM(B38:I38) -> 0
A39: c.3. Horas en actividades comunitarias | J39: =SUM(B39:I39) -> 0
A40: 2.4 OTRAS HORAS
A41: d.Total de Horas no operativas en servicio dentro de la base o puesto (stand by: espera por alerta de narcotráfico, espera por logística, espera por alguna situación ). | J41: =SUM(B41:I41) -> 0
...

Sheet SNG-25
A1: SERVICIO NACIONAL DE GUARDACOSTAS Ministerio Seguridad Pública REGISTRO DE RESULTADOS OPERATIVOS , AÑO 2026
A3: ESTACIÓN DE GUARDACOSTAS: | B3: =IF(ESTACIÓN!B3="","",ESTACIÓN!B3) -> MURCIELAGO
A4: UNIDAD: | B4: =IF(ESTACIÓN!B4="","",ESTACIÓN!B4)
A5: SEMANA: | B5: =IF(ESTACIÓN!D5="","",ESTACIÓN!D5) -> 46113 | F5: al | G5: =IF(ESTACIÓN!I5="","",ESTACIÓN!I5) -> 46120
A6: CIERRE DE ORDEN | B6: =IF(ESTACIÓN!B6="","",ESTACIÓN!B6) -> 12
A7: NÚMERO DE REPORTE DE VIAJE:
A8: ITEM/DIA | B8: =ESTACIÓN!$B$8 -> 46113 | C8: =ESTACIÓN!$C$8 -> 46114 | D8: =ESTACIÓN!$D$8 -> 46115 | E8: =ESTACIÓN!$E$8 -> 46116 | F8: =ESTACIÓN!$F$8 -> 46117 | G8: =ESTACIÓN!$G$8 -> 46118 | H8: =ESTACIÓN!$H$8 -> 46119 | I8: =ESTACIÓN!$I$8 -> 46120 | J8: TOTAL
A9: 1. RECURSOS INVERTIDOS
A10: a. Millas recorridas por embarcación durante el patrullaje | J10: =SUM(B10:I10) -> 0 | U10: =COUNT(J10:J277) -> 250 | V10: =COUNTIF(J10:J277,"0") -> 250
A11: b. Kilómetros recorridos por el vehículo durante el patrullaje | J11: =SUM(B11:I11) -> 0
A12: c. Kilómetros recorridos caminando durante el patrullaje | J12: =SUM(B12:I12) -> 0
A13: d. Horas navegadas | J13: =SUM(B13:I13) -> 0
A14: e. Horas motor | J14: =SUM(B14:I14) -> 0
A15: f. Litros de gasolina abastecidos previos al patrullaje | J15: =SUM(B15:I15) -> 0
A16: g. Litros de gasolina consumidos durante el patrullaje | J16: =SUM(B16:I16) -> 0
A17: h. Litros de diesel abastecido previos al patrullaje | J17: =SUM(B17:I17) -> 0
A18: i. Litros de diesel consumidos durante el patrullaje | J18: =SUM(B18:I18) -> 0
A19: j. Consumo de aceite de mezcla durante patrullaje (cuartos) | J19: =SUM(B19:I19) -> 0
A20: k. Consumo de aceite de motor (galones) | J20: =SUM(B20:I20) -> 0
A21: 2. HORAS LABORADAS
A22: 2.1. HORAS OPERATIVAS
A23: a. Total de Horas Opertativas en patrullajes o puesto fijos
A24: a.1. Horas operativas en patrullajes y puestos fijos | J24: =SUM(B24:I24) -> 0
A25: 2.2. HORAS EN GESTION OPERATIVA DE APOYO
A26: b. Total de horas en apoyo logístico | B26: =SUM(B27:B34) -> 0 | C26: =SUM(C27:C34) -> 0 | D26: =SUM(D27:D34) -> 0 | E26: =SUM(E27:E34) -> 0 | F26: =SUM(F27:F34) -> 0 | G26: =SUM(G27:G34) -> 0 | H26: =SUM(H27:H34) -> 0 | I26: =SUM(I27:I34) -> 0 | J26: =SUM(B26:I26) -> 0
A27: b.1. Horas planificación, dirección, coordinación, supervisión. | J27: =SUM(B27:I27) -> 0
A28: b.2. Horas operativas en oficialía de guardia y vigilancia perimetral | J28: =SUM(B28:I28) -> 0
A29: b.3. Horas en procesos judiciales o administrativos | J29: =SUM(B29:I29) -> 0
A30: b.4. Horas en elaboración de documentos oficiales | J30: =SUM(B30:I30) -> 0
A31: b.5. Horas en mantenimiento de activos utilizados para patrullajes. | J31: =SUM(B31:I31) -> 0
A32: b.6. Horas en ornato, aseo de la Estación y/o Puesto, horas en mantenimiento de activos no utilizados para patrullaje, labores de preparación de alimentos, carga, descarga, transbordo de global y suministros (logística relacionada a alimentación y suministros en general) | J32: =SUM(B32:I32) -> 0
A33: b.7. Horas en reuniones | J33: =SUM(B33:I33) -> 0
A34: b.8 Horas Acondicionamiento Fisico | J34: =SUM(B34:I34) -> 0
A35: 2.3 HORAS EN PROYECCIÓN SOCIAL Y CAPACITACIÓN
A36: c. Total de horas proyección social y formación | B36: =SUM(B37:B39) -> 0 | C36: =SUM(C37:C39) -> 0 | D36: =SUM(D37:D39) -> 0 | E36: =SUM(E37:E39) -> 0 | F36: =SUM(F37:F39) -> 0 | G36: =SUM(G37:G39) -> 0 | H36: =SUM(H37:H39) -> 0 | I36: =SUM(I37:I39) -> 0 | J36: =SUM(B36:I36) -> 0
A37: c.1. Horas en charlas, talleres, capacitaciones impartidas | J37: =SUM(B37:I37) -> 0
A38: c.2. Horas en charlas, talleres, capacitaciones recibidas | J38: =SUM(B38:I38) -> 0
A39: c.3. Horas en actividades comunitarias | J39: =SUM(B39:I39) -> 0
A40: 2.4 OTRAS HORAS
A41: d.Total de Horas no operativas en servicio dentro de la base o puesto (stand by: espera por alerta de narcotráfico, espera por logística, espera por alguna situación ). | J41: =SUM(B41:I41) -> 0
...

Sheet GC-38-11
A1: SERVICIO NACIONAL DE GUARDACOSTAS Ministerio Seguridad Pública REGISTRO DE RESULTADOS OPERATIVOS , AÑO 2026
A3: ESTACIÓN DE GUARDACOSTAS: | B3: =IF(ESTACIÓN!B3="","",ESTACIÓN!B3) -> MURCIELAGO
A4: UNIDAD: | B4: =IF(ESTACIÓN!B4="","",ESTACIÓN!B4)
A5: SEMANA: | B5: =IF(ESTACIÓN!D5="","",ESTACIÓN!D5) -> 46113 | F5: al | G5: =IF(ESTACIÓN!I5="","",ESTACIÓN!I5) -> 46120
A6: CIERRE DE ORDEN | B6: =IF(ESTACIÓN!B6="","",ESTACIÓN!B6) -> 12
A7: NÚMERO DE REPORTE DE VIAJE:
A8: ITEM/DIA | B8: =ESTACIÓN!$B$8 -> 46113 | C8: =ESTACIÓN!$C$8 -> 46114 | D8: =ESTACIÓN!$D$8 -> 46115 | E8: =ESTACIÓN!$E$8 -> 46116 | F8: =ESTACIÓN!$F$8 -> 46117 | G8: =ESTACIÓN!$G$8 -> 46118 | H8: =ESTACIÓN!$H$8 -> 46119 | I8: =ESTACIÓN!$I$8 -> 46120 | J8: TOTAL
A9: 1. RECURSOS INVERTIDOS
A10: a. Millas recorridas por embarcación durante el patrullaje | J10: =SUM(B10:I10) -> 0 | U10: =COUNT(J10:J277) -> 250 | V10: =COUNTIF(J10:J277,"0") -> 250
A11: b. Kilómetros recorridos por el vehículo durante el patrullaje | J11: =SUM(B11:I11) -> 0
A12: c. Kilómetros recorridos caminando durante el patrullaje | J12: =SUM(B12:I12) -> 0
A13: d. Horas navegadas | J13: =SUM(B13:I13) -> 0
A14: e. Horas motor | J14: =SUM(B14:I14) -> 0
A15: f. Litros de gasolina abastecidos previos al patrullaje | J15: =SUM(B15:I15) -> 0
A16: g. Litros de gasolina consumidos durante el patrullaje | J16: =SUM(B16:I16) -> 0
A17: h. Litros de diesel abastecido previos al patrullaje | J17: =SUM(B17:I17) -> 0
A18: i. Litros de diesel consumidos durante el patrullaje | J18: =SUM(B18:I18) -> 0
A19: j. Consumo de aceite de mezcla durante patrullaje (cuartos) | J19: =SUM(B19:I19) -> 0
A20: k. Consumo de aceite de motor (galones) | J20: =SUM(B20:I20) -> 0
A21: 2. HORAS LABORADAS
A22: 2.1. HORAS OPERATIVAS
A23: a. Total de Horas Opertativas en patrullajes o puesto fijos
A24: a.1. Horas operativas en patrullajes y puestos fijos | J24: =SUM(B24:I24) -> 0
A25: 2.2. HORAS EN GESTION OPERATIVA DE APOYO
A26: b. Total de horas en apoyo logístico | B26: =SUM(B27:B34) -> 0 | C26: =SUM(C27:C34) -> 0 | D26: =SUM(D27:D34) -> 0 | E26: =SUM(E27:E34) -> 0 | F26: =SUM(F27:F34) -> 0 | G26: =SUM(G27:G34) -> 0 | H26: =SUM(H27:H34) -> 0 | I26: =SUM(I27:I34) -> 0 | J26: =SUM(B26:I26) -> 0
A27: b.1. Horas planificación, dirección, coordinación, supervisión. | J27: =SUM(B27:I27) -> 0
A28: b.2. Horas operativas en oficialía de guardia y vigilancia perimetral | J28: =SUM(B28:I28) -> 0
A29: b.3. Horas en procesos judiciales o administrativos | J29: =SUM(B29:I29) -> 0
A30: b.4. Horas en elaboración de documentos oficiales | J30: =SUM(B30:I30) -> 0
A31: b.5. Horas en mantenimiento de activos utilizados para patrullajes. | J31: =SUM(B31:I31) -> 0
A32: b.6. Horas en ornato, aseo de la Estación y/o Puesto, horas en mantenimiento de activos no utilizados para patrullaje, labores de preparación de alimentos, carga, descarga, transbordo de global y suministros (logística relacionada a alimentación y suministros en general) | J32: =SUM(B32:I32) -> 0
A33: b.7. Horas en reuniones | J33: =SUM(B33:I33) -> 0
A34: b.8 Horas Acondicionamiento Fisico | J34: =SUM(B34:I34) -> 0
A35: 2.3 HORAS EN PROYECCIÓN SOCIAL Y CAPACITACIÓN
A36: c. Total de horas proyección social y formación | B36: =SUM(B37:B39) -> 0 | C36: =SUM(C37:C39) -> 0 | D36: =SUM(D37:D39) -> 0 | E36: =SUM(E37:E39) -> 0 | F36: =SUM(F37:F39) -> 0 | G36: =SUM(G37:G39) -> 0 | H36: =SUM(H37:H39) -> 0 | I36: =SUM(I37:I39) -> 0 | J36: =SUM(B36:I36) -> 0
A37: c.1. Horas en charlas, talleres, capacitaciones impartidas | J37: =SUM(B37:I37) -> 0
A38: c.2. Horas en charlas, talleres, capacitaciones recibidas | J38: =SUM(B38:I38) -> 0
A39: c.3. Horas en actividades comunitarias | J39: =SUM(B39:I39) -> 0
A40: 2.4 OTRAS HORAS
A41: d.Total de Horas no operativas en servicio dentro de la base o puesto (stand by: espera por alerta de narcotráfico, espera por logística, espera por alguna situación ). | J41: =SUM(B41:I41) -> 0
...

Sheet GC-38-22
A1: SERVICIO NACIONAL DE GUARDACOSTAS Ministerio Seguridad Pública REGISTRO DE RESULTADOS OPERATIVOS , AÑO 2026
A3: ESTACIÓN DE GUARDACOSTAS: | B3: =IF(ESTACIÓN!B3="","",ESTACIÓN!B3) -> MURCIELAGO
A4: UNIDAD: | B4: =IF(ESTACIÓN!B4="","",ESTACIÓN!B4)
A5: SEMANA: | B5: =IF(ESTACIÓN!D5="","",ESTACIÓN!D5) -> 46113 | F5: al | G5: =IF(ESTACIÓN!I5="","",ESTACIÓN!I5) -> 46120
A6: CIERRE DE ORDEN | B6: =IF(ESTACIÓN!B6="","",ESTACIÓN!B6) -> 12
A7: NÚMERO DE REPORTE DE VIAJE:
A8: ITEM/DIA | B8: =ESTACIÓN!$B$8 -> 46113 | C8: =ESTACIÓN!$C$8 -> 46114 | D8: =ESTACIÓN!$D$8 -> 46115 | E8: =ESTACIÓN!$E$8 -> 46116 | F8: =ESTACIÓN!$F$8 -> 46117 | G8: =ESTACIÓN!$G$8 -> 46118 | H8: =ESTACIÓN!$H$8 -> 46119 | I8: =ESTACIÓN!$I$8 -> 46120 | J8: TOTAL
A9: 1. RECURSOS INVERTIDOS
A10: a. Millas recorridas por embarcación durante el patrullaje | J10: =SUM(B10:I10) -> 0 | U10: =COUNT(J10:J277) -> 250 | V10: =COUNTIF(J10:J277,"0") -> 250
A11: b. Kilómetros recorridos por el vehículo durante el patrullaje | J11: =SUM(B11:I11) -> 0
A12: c. Kilómetros recorridos caminando durante el patrullaje | J12: =SUM(B12:I12) -> 0
A13: d. Horas navegadas | J13: =SUM(B13:I13) -> 0
A14: e. Horas motor | J14: =SUM(B14:I14) -> 0
A15: f. Litros de gasolina abastecidos previos al patrullaje | J15: =SUM(B15:I15) -> 0
A16: g. Litros de gasolina consumidos durante el patrullaje | J16: =SUM(B16:I16) -> 0
A17: h. Litros de diesel abastecido previos al patrullaje | J17: =SUM(B17:I17) -> 0
A18: i. Litros de diesel consumidos durante el patrullaje | J18: =SUM(B18:I18) -> 0
A19: j. Consumo de aceite de mezcla durante patrullaje (cuartos) | J19: =SUM(B19:I19) -> 0
A20: k. Consumo de aceite de motor (galones) | J20: =SUM(B20:I20) -> 0
A21: 2. HORAS LABORADAS
A22: 2.1. HORAS OPERATIVAS
A23: a. Total de Horas Opertativas en patrullajes o puesto fijos
A24: a.1. Horas operativas en patrullajes y puestos fijos | J24: =SUM(B24:I24) -> 0
A25: 2.2. HORAS EN GESTION OPERATIVA DE APOYO
A26: b. Total de horas en apoyo logístico | B26: =SUM(B27:B34) -> 0 | C26: =SUM(C27:C34) -> 0 | D26: =SUM(D27:D34) -> 0 | E26: =SUM(E27:E34) -> 0 | F26: =SUM(F27:F34) -> 0 | G26: =SUM(G27:G34) -> 0 | H26: =SUM(H27:H34) -> 0 | I26: =SUM(I27:I34) -> 0 | J26: =SUM(B26:I26) -> 0
A27: b.1. Horas planificación, dirección, coordinación, supervisión. | J27: =SUM(B27:I27) -> 0
A28: b.2. Horas operativas en oficialía de guardia y vigilancia perimetral | J28: =SUM(B28:I28) -> 0
A29: b.3. Horas en procesos judiciales o administrativos | J29: =SUM(B29:I29) -> 0
A30: b.4. Horas en elaboración de documentos oficiales | J30: =SUM(B30:I30) -> 0
A31: b.5. Horas en mantenimiento de activos utilizados para patrullajes. | J31: =SUM(B31:I31) -> 0
A32: b.6. Horas en ornato, aseo de la Estación y/o Puesto, horas en mantenimiento de activos no utilizados para patrullaje, labores de preparación de alimentos, carga, descarga, transbordo de global y suministros (logística relacionada a alimentación y suministros en general) | J32: =SUM(B32:I32) -> 0
A33: b.7. Horas en reuniones | J33: =SUM(B33:I33) -> 0
A34: b.8 Horas Acondicionamiento Fisico | J34: =SUM(B34:I34) -> 0
A35: 2.3 HORAS EN PROYECCIÓN SOCIAL Y CAPACITACIÓN
A36: c. Total de horas proyección social y formación | B36: =SUM(B37:B39) -> 0 | C36: =SUM(C37:C39) -> 0 | D36: =SUM(D37:D39) -> 0 | E36: =SUM(E37:E39) -> 0 | F36: =SUM(F37:F39) -> 0 | G36: =SUM(G37:G39) -> 0 | H36: =SUM(H37:H39) -> 0 | I36: =SUM(I37:I39) -> 0 | J36: =SUM(B36:I36) -> 0
A37: c.1. Horas en charlas, talleres, capacitaciones impartidas | J37: =SUM(B37:I37) -> 0
A38: c.2. Horas en charlas, talleres, capacitaciones recibidas | J38: =SUM(B38:I38) -> 0
A39: c.3. Horas en actividades comunitarias | J39: =SUM(B39:I39) -> 0
A40: 2.4 OTRAS HORAS
A41: d.Total de Horas no operativas en servicio dentro de la base o puesto (stand by: espera por alerta de narcotráfico, espera por logística, espera por alguna situación ). | J41: =SUM(B41:I41) -> 0
...

Sheet MEGAOP
A1: SERVICIO NACIONAL DE GUARDACOSTAS Ministerio Seguridad Pública REGISTRO DE RESULTADOS OPERATIVOS , AÑO 2026
A3: ESTACIÓN DE GUARDACOSTAS: | B3: =IF(ESTACIÓN!B3="","",ESTACIÓN!B3) -> MURCIELAGO
A4: UNIDAD: | B4: =IF(ESTACIÓN!B4="","",ESTACIÓN!B4)
A5: SEMANA: | B5: =IF(ESTACIÓN!D5="","",ESTACIÓN!D5) -> 46113 | F5: al | G5: =IF(ESTACIÓN!I5="","",ESTACIÓN!I5) -> 46120
A6: CIERRE DE ORDEN | B6: =IF(ESTACIÓN!B6="","",ESTACIÓN!B6) -> 12
A7: NÚMERO DE REPORTE DE VIAJE:
A8: ITEM/DIA | B8: =ESTACIÓN!$B$8 -> 46113 | C8: =ESTACIÓN!$C$8 -> 46114 | D8: =ESTACIÓN!$D$8 -> 46115 | E8: =ESTACIÓN!$E$8 -> 46116 | F8: =ESTACIÓN!$F$8 -> 46117 | G8: =ESTACIÓN!$G$8 -> 46118 | H8: =ESTACIÓN!$H$8 -> 46119 | I8: =ESTACIÓN!$I$8 -> 46120 | J8: TOTAL
A9: 1. RECURSOS INVERTIDOS
A10: a. Millas recorridas por embarcación durante el patrullaje | J10: =SUM(B10:I10) -> 0 | U10: =COUNT(J10:J277) -> 250 | V10: =COUNTIF(J10:J277,"0") -> 250
A11: b. Kilómetros recorridos por el vehículo durante el patrullaje | J11: =SUM(B11:I11) -> 0
A12: c. Kilómetros recorridos caminando durante el patrullaje | J12: =SUM(B12:I12) -> 0
A13: d. Horas navegadas | J13: =SUM(B13:I13) -> 0
A14: e. Horas motor | J14: =SUM(B14:I14) -> 0
A15: f. Litros de gasolina abastecidos previos al patrullaje | J15: =SUM(B15:I15) -> 0
A16: g. Litros de gasolina consumidos durante el patrullaje | J16: =SUM(B16:I16) -> 0
A17: h. Litros de diesel abastecido previos al patrullaje | J17: =SUM(B17:I17) -> 0
A18: i. Litros de diesel consumidos durante el patrullaje | J18: =SUM(B18:I18) -> 0
A19: j. Consumo de aceite de mezcla durante patrullaje (cuartos) | J19: =SUM(B19:I19) -> 0
A20: k. Consumo de aceite de motor (galones) | J20: =SUM(B20:I20) -> 0
A21: 2. HORAS LABORADAS
A22: 2.1. HORAS OPERATIVAS
A23: a. Total de Horas Opertativas en patrullajes o puesto fijos
A24: a.1. Horas operativas en patrullajes y puestos fijos | J24: =SUM(B24:I24) -> 0
A25: 2.2. HORAS EN GESTION OPERATIVA DE APOYO
A26: b. Total de horas en apoyo logístico | B26: =SUM(B27:B34) -> 0 | C26: =SUM(C27:C34) -> 0 | D26: =SUM(D27:D34) -> 0 | E26: =SUM(E27:E34) -> 0 | F26: =SUM(F27:F34) -> 0 | G26: =SUM(G27:G34) -> 0 | H26: =SUM(H27:H34) -> 0 | I26: =SUM(I27:I34) -> 0 | J26: =SUM(B26:I26) -> 0
A27: b.1. Horas planificación, dirección, coordinación, supervisión. | J27: =SUM(B27:I27) -> 0
A28: b.2. Horas operativas en oficialía de guardia y vigilancia perimetral | J28: =SUM(B28:I28) -> 0
A29: b.3. Horas en procesos judiciales o administrativos | J29: =SUM(B29:I29) -> 0
A30: b.4. Horas en elaboración de documentos oficiales | J30: =SUM(B30:I30) -> 0
A31: b.5. Horas en mantenimiento de activos utilizados para patrullajes. | J31: =SUM(B31:I31) -> 0
A32: b.6. Horas en ornato, aseo de la Estación y/o Puesto, horas en mantenimiento de activos no utilizados para patrullaje, labores de preparación de alimentos, carga, descarga, transbordo de global y suministros (logística relacionada a alimentación y suministros en general) | J32: =SUM(B32:I32) -> 0
A33: b.7. Horas en reuniones | J33: =SUM(B33:I33) -> 0
A34: b.8 Horas Acondicionamiento Fisico | J34: =SUM(B34:I34) -> 0
A35: 2.3 HORAS EN PROYECCIÓN SOCIAL Y CAPACITACIÓN
A36: c. Total de horas proyección social y formación | B36: =SUM(B37:B39) -> 0 | C36: =SUM(C37:C39) -> 0 | D36: =SUM(D37:D39) -> 0 | E36: =SUM(E37:E39) -> 0 | F36: =SUM(F37:F39) -> 0 | G36: =SUM(G37:G39) -> 0 | H36: =SUM(H37:H39) -> 0 | I36: =SUM(I37:I39) -> 0 | J36: =SUM(B36:I36) -> 0
A37: c.1. Horas en charlas, talleres, capacitaciones impartidas | J37: =SUM(B37:I37) -> 0
A38: c.2. Horas en charlas, talleres, capacitaciones recibidas | J38: =SUM(B38:I38) -> 0
A39: c.3. Horas en actividades comunitarias | J39: =SUM(B39:I39) -> 0
A40: 2.4 OTRAS HORAS
A41: d.Total de Horas no operativas en servicio dentro de la base o puesto (stand by: espera por alerta de narcotráfico, espera por logística, espera por alguna situación ). | J41: =SUM(B41:I41) -> 0
...

Sheet CAMINANDO
A1: SERVICIO NACIONAL DE GUARDACOSTAS Ministerio Seguridad Pública REGISTRO DE RESULTADOS OPERATIVOS , AÑO 2026
A3: ESTACIÓN DE GUARDACOSTAS: | B3: =IF(ESTACIÓN!B3="","",ESTACIÓN!B3) -> MURCIELAGO
A4: UNIDAD: | B4: =IF(ESTACIÓN!B4="","",ESTACIÓN!B4)
A5: SEMANA: | B5: =IF(ESTACIÓN!D5="","",ESTACIÓN!D5) -> 46113 | F5: al | G5: =IF(ESTACIÓN!I5="","",ESTACIÓN!I5) -> 46120
A6: CIERRE DE ORDEN | B6: =IF(ESTACIÓN!B6="","",ESTACIÓN!B6) -> 12
A7: NÚMERO DE REPORTE DE VIAJE:
A8: ITEM/DIA | B8: =ESTACIÓN!$B$8 -> 46113 | C8: =ESTACIÓN!$C$8 -> 46114 | D8: =ESTACIÓN!$D$8 -> 46115 | E8: =ESTACIÓN!$E$8 -> 46116 | F8: =ESTACIÓN!$F$8 -> 46117 | G8: =ESTACIÓN!$G$8 -> 46118 | H8: =ESTACIÓN!$H$8 -> 46119 | I8: =ESTACIÓN!$I$8 -> 46120 | J8: TOTAL
A9: 1. RECURSOS INVERTIDOS
A10: a. Millas recorridas por embarcación durante el patrullaje | J10: =SUM(B10:I10) -> 0 | U10: =COUNT(J10:J277) -> 250 | V10: =COUNTIF(J10:J277,"0") -> 250
A11: b. Kilómetros recorridos por el vehículo durante el patrullaje | J11: =SUM(B11:I11) -> 0
A12: c. Kilómetros recorridos caminando durante el patrullaje | J12: =SUM(B12:I12) -> 0
A13: d. Horas navegadas | J13: =SUM(B13:I13) -> 0
A14: e. Horas motor | J14: =SUM(B14:I14) -> 0
A15: f. Litros de gasolina abastecidos previos al patrullaje | J15: =SUM(B15:I15) -> 0
A16: g. Litros de gasolina consumidos durante el patrullaje | J16: =SUM(B16:I16) -> 0
A17: h. Litros de diesel abastecido previos al patrullaje | J17: =SUM(B17:I17) -> 0
A18: i. Litros de diesel consumidos durante el patrullaje | J18: =SUM(B18:I18) -> 0
A19: j. Consumo de aceite de mezcla durante patrullaje (cuartos) | J19: =SUM(B19:I19) -> 0
A20: k. Consumo de aceite de motor (galones) | J20: =SUM(B20:I20) -> 0
A21: 2. HORAS LABORADAS
A22: 2.1. HORAS OPERATIVAS
A23: a. Total de Horas Opertativas en patrullajes o puesto fijos
A24: a.1. Horas operativas en patrullajes y puestos fijos | J24: =SUM(B24:I24) -> 0
A25: 2.2. HORAS EN GESTION OPERATIVA DE APOYO
A26: b. Total de horas en apoyo logístico | B26: =SUM(B27:B34) -> 0 | C26: =SUM(C27:C34) -> 0 | D26: =SUM(D27:D34) -> 0 | E26: =SUM(E27:E34) -> 0 | F26: =SUM(F27:F34) -> 0 | G26: =SUM(G27:G34) -> 0 | H26: =SUM(H27:H34) -> 0 | I26: =SUM(I27:I34) -> 0 | J26: =SUM(B26:I26) -> 0
A27: b.1. Horas planificación, dirección, coordinación, supervisión. | J27: =SUM(B27:I27) -> 0
A28: b.2. Horas operativas en oficialía de guardia y vigilancia perimetral | J28: =SUM(B28:I28) -> 0
A29: b.3. Horas en procesos judiciales o administrativos | J29: =SUM(B29:I29) -> 0
A30: b.4. Horas en elaboración de documentos oficiales | J30: =SUM(B30:I30) -> 0
A31: b.5. Horas en mantenimiento de activos utilizados para patrullajes. | J31: =SUM(B31:I31) -> 0
A32: b.6. Horas en ornato, aseo de la Estación y/o Puesto, horas en mantenimiento de activos no utilizados para patrullaje, labores de preparación de alimentos, carga, descarga, transbordo de global y suministros (logística relacionada a alimentación y suministros en general) | J32: =SUM(B32:I32) -> 0
A33: b.7. Horas en reuniones | J33: =SUM(B33:I33) -> 0
A34: b.8 Horas Acondicionamiento Fisico | J34: =SUM(B34:I34) -> 0
A35: 2.3 HORAS EN PROYECCIÓN SOCIAL Y CAPACITACIÓN
A36: c. Total de horas proyección social y formación | B36: =SUM(B37:B39) -> 0 | C36: =SUM(C37:C39) -> 0 | D36: =SUM(D37:D39) -> 0 | E36: =SUM(E37:E39) -> 0 | F36: =SUM(F37:F39) -> 0 | G36: =SUM(G37:G39) -> 0 | H36: =SUM(H37:H39) -> 0 | I36: =SUM(I37:I39) -> 0 | J36: =SUM(B36:I36) -> 0
A37: c.1. Horas en charlas, talleres, capacitaciones impartidas | J37: =SUM(B37:I37) -> 0
A38: c.2. Horas en charlas, talleres, capacitaciones recibidas | J38: =SUM(B38:I38) -> 0
A39: c.3. Horas en actividades comunitarias | J39: =SUM(B39:I39) -> 0
A40: 2.4 OTRAS HORAS
A41: d.Total de Horas no operativas en servicio dentro de la base o puesto (stand by: espera por alerta de narcotráfico, espera por logística, espera por alguna situación ). | J41: =SUM(B41:I41) -> 0
...

Sheet APOYO
A1: SERVICIO NACIONAL DE GUARDACOSTAS Ministerio Seguridad Pública REGISTRO DE RESULTADOS OPERATIVOS , AÑO 2026
A3: ESTACIÓN DE GUARDACOSTAS: | B3: =IF(ESTACIÓN!B3="","",ESTACIÓN!B3) -> MURCIELAGO
A4: UNIDAD: | B4: =IF(ESTACIÓN!B4="","",ESTACIÓN!B4)
A5: SEMANA: | B5: =IF(ESTACIÓN!D5="","",ESTACIÓN!D5) -> 46113 | F5: al | G5: =IF(ESTACIÓN!I5="","",ESTACIÓN!I5) -> 46120
A6: CIERRE DE ORDEN | B6: =IF(ESTACIÓN!B6="","",ESTACIÓN!B6) -> 12
A7: NÚMERO DE REPORTE DE VIAJE:
A8: ITEM/DIA | B8: =ESTACIÓN!$B$8 -> 46113 | C8: =ESTACIÓN!$C$8 -> 46114 | D8: =ESTACIÓN!$D$8 -> 46115 | E8: =ESTACIÓN!$E$8 -> 46116 | F8: =ESTACIÓN!$F$8 -> 46117 | G8: =ESTACIÓN!$G$8 -> 46118 | H8: =ESTACIÓN!$H$8 -> 46119 | I8: =ESTACIÓN!$I$8 -> 46120 | J8: TOTAL
A9: 1. RECURSOS INVERTIDOS
A10: a. Millas recorridas por embarcación durante el patrullaje | J10: =SUM(B10:I10) -> 0 | U10: =COUNT(J10:J277) -> 250 | V10: =COUNTIF(J10:J277,"0") -> 250
A11: b. Kilómetros recorridos por el vehículo durante el patrullaje | J11: =SUM(B11:I11) -> 0
A12: c. Kilómetros recorridos caminando durante el patrullaje | J12: =SUM(B12:I12) -> 0
A13: d. Horas navegadas | J13: =SUM(B13:I13) -> 0
A14: e. Horas motor | J14: =SUM(B14:I14) -> 0
A15: f. Litros de gasolina abastecidos previos al patrullaje | J15: =SUM(B15:I15) -> 0
A16: g. Litros de gasolina consumidos durante el patrullaje | J16: =SUM(B16:I16) -> 0
A17: h. Litros de diesel abastecido previos al patrullaje | J17: =SUM(B17:I17) -> 0
A18: i. Litros de diesel consumidos durante el patrullaje | J18: =SUM(B18:I18) -> 0
A19: j. Consumo de aceite de mezcla durante patrullaje (cuartos) | J19: =SUM(B19:I19) -> 0
A20: k. Consumo de aceite de motor (galones) | J20: =SUM(B20:I20) -> 0
A21: 2. HORAS LABORADAS
A22: 2.1. HORAS OPERATIVAS
A23: a. Total de Horas Opertativas en patrullajes o puesto fijos
A24: a.1. Horas operativas en patrullajes y puestos fijos | J24: =SUM(B24:I24) -> 0
A25: 2.2. HORAS EN GESTION OPERATIVA DE APOYO
A26: b. Total de horas en apoyo logístico | B26: =SUM(B27:B34) -> 0 | C26: =SUM(C27:C34) -> 0 | D26: =SUM(D27:D34) -> 0 | E26: =SUM(E27:E34) -> 0 | F26: =SUM(F27:F34) -> 0 | G26: =SUM(G27:G34) -> 0 | H26: =SUM(H27:H34) -> 0 | I26: =SUM(I27:I34) -> 0 | J26: =SUM(B26:I26) -> 0
A27: b.1. Horas planificación, dirección, coordinación, supervisión. | J27: =SUM(B27:I27) -> 0
A28: b.2. Horas operativas en oficialía de guardia y vigilancia perimetral | J28: =SUM(B28:I28) -> 0
A29: b.3. Horas en procesos judiciales o administrativos | J29: =SUM(B29:I29) -> 0
A30: b.4. Horas en elaboración de documentos oficiales | J30: =SUM(B30:I30) -> 0
A31: b.5. Horas en mantenimiento de activos utilizados para patrullajes. | J31: =SUM(B31:I31) -> 0
A32: b.6. Horas en ornato, aseo de la Estación y/o Puesto, horas en mantenimiento de activos no utilizados para patrullaje, labores de preparación de alimentos, carga, descarga, transbordo de global y suministros (logística relacionada a alimentación y suministros en general) | J32: =SUM(B32:I32) -> 0
A33: b.7. Horas en reuniones | J33: =SUM(B33:I33) -> 0
A34: b.8 Horas Acondicionamiento Fisico | J34: =SUM(B34:I34) -> 0
A35: 2.3 HORAS EN PROYECCIÓN SOCIAL Y CAPACITACIÓN
A36: c. Total de horas proyección social y formación | B36: =SUM(B37:B39) -> 0 | C36: =SUM(C37:C39) -> 0 | D36: =SUM(D37:D39) -> 0 | E36: =SUM(E37:E39) -> 0 | F36: =SUM(F37:F39) -> 0 | G36: =SUM(G37:G39) -> 0 | H36: =SUM(H37:H39) -> 0 | I36: =SUM(I37:I39) -> 0 | J36: =SUM(B36:I36) -> 0
A37: c.1. Horas en charlas, talleres, capacitaciones impartidas | J37: =SUM(B37:I37) -> 0
A38: c.2. Horas en charlas, talleres, capacitaciones recibidas | J38: =SUM(B38:I38) -> 0
A39: c.3. Horas en actividades comunitarias | J39: =SUM(B39:I39) -> 0
A40: 2.4 OTRAS HORAS
A41: d.Total de Horas no operativas en servicio dentro de la base o puesto (stand by: espera por alerta de narcotráfico, espera por logística, espera por alguna situación ). | J41: =SUM(B41:I41) -> 0
...

Sheet OTRO
A1: SERVICIO NACIONAL DE GUARDACOSTAS Ministerio Seguridad Pública REGISTRO DE RESULTADOS OPERATIVOS , AÑO 2026
A3: ESTACIÓN DE GUARDACOSTAS: | B3: =IF(ESTACIÓN!B3="","",ESTACIÓN!B3) -> MURCIELAGO
A4: UNIDAD: | B4: =IF(ESTACIÓN!B4="","",ESTACIÓN!B4)
A5: SEMANA: | B5: =IF(ESTACIÓN!D5="","",ESTACIÓN!D5) -> 46113 | F5: al | G5: =IF(ESTACIÓN!I5="","",ESTACIÓN!I5) -> 46120
A6: CIERRE DE ORDEN | B6: =IF(ESTACIÓN!B6="","",ESTACIÓN!B6) -> 12
A7: NÚMERO DE REPORTE DE VIAJE:
A8: ITEM/DIA | B8: =ESTACIÓN!$B$8 -> 46113 | C8: =ESTACIÓN!$C$8 -> 46114 | D8: =ESTACIÓN!$D$8 -> 46115 | E8: =ESTACIÓN!$E$8 -> 46116 | F8: =ESTACIÓN!$F$8 -> 46117 | G8: =ESTACIÓN!$G$8 -> 46118 | H8: =ESTACIÓN!$H$8 -> 46119 | I8: =ESTACIÓN!$I$8 -> 46120 | J8: TOTAL
A9: 1. RECURSOS INVERTIDOS
A10: a. Millas recorridas por embarcación durante el patrullaje | J10: =SUM(B10:I10) -> 0 | U10: =COUNT(J10:J277) -> 250 | V10: =COUNTIF(J10:J277,"0") -> 250
A11: b. Kilómetros recorridos por el vehículo durante el patrullaje | J11: =SUM(B11:I11) -> 0
A12: c. Kilómetros recorridos caminando durante el patrullaje | J12: =SUM(B12:I12) -> 0
A13: d. Horas navegadas | J13: =SUM(B13:I13) -> 0
A14: e. Horas motor | J14: =SUM(B14:I14) -> 0
A15: f. Litros de gasolina abastecidos previos al patrullaje | J15: =SUM(B15:I15) -> 0
A16: g. Litros de gasolina consumidos durante el patrullaje | J16: =SUM(B16:I16) -> 0
A17: h. Litros de diesel abastecido previos al patrullaje | J17: =SUM(B17:I17) -> 0
A18: i. Litros de diesel consumidos durante el patrullaje | J18: =SUM(B18:I18) -> 0
A19: j. Consumo de aceite de mezcla durante patrullaje (cuartos) | J19: =SUM(B19:I19) -> 0
A20: k. Consumo de aceite de motor (galones) | J20: =SUM(B20:I20) -> 0
A21: 2. HORAS LABORADAS
A22: 2.1. HORAS OPERATIVAS
A23: a. Total de Horas Opertativas en patrullajes o puesto fijos
A24: a.1. Horas operativas en patrullajes y puestos fijos | J24: =SUM(B24:I24) -> 0
A25: 2.2. HORAS EN GESTION OPERATIVA DE APOYO
A26: b. Total de horas en apoyo logístico | B26: =SUM(B27:B34) -> 0 | C26: =SUM(C27:C34) -> 0 | D26: =SUM(D27:D34) -> 0 | E26: =SUM(E27:E34) -> 0 | F26: =SUM(F27:F34) -> 0 | G26: =SUM(G27:G34) -> 0 | H26: =SUM(H27:H34) -> 0 | I26: =SUM(I27:I34) -> 0 | J26: =SUM(B26:I26) -> 0
A27: b.1. Horas planificación, dirección, coordinación, supervisión. | J27: =SUM(B27:I27) -> 0
A28: b.2. Horas operativas en oficialía de guardia y vigilancia perimetral | J28: =SUM(B28:I28) -> 0
A29: b.3. Horas en procesos judiciales o administrativos | J29: =SUM(B29:I29) -> 0
A30: b.4. Horas en elaboración de documentos oficiales | J30: =SUM(B30:I30) -> 0
A31: b.5. Horas en mantenimiento de activos utilizados para patrullajes. | J31: =SUM(B31:I31) -> 0
A32: b.6. Horas en ornato, aseo de la Estación y/o Puesto, horas en mantenimiento de activos no utilizados para patrullaje, labores de preparación de alimentos, carga, descarga, transbordo de global y suministros (logística relacionada a alimentación y suministros en general) | J32: =SUM(B32:I32) -> 0
A33: b.7. Horas en reuniones | J33: =SUM(B33:I33) -> 0
A34: b.8 Horas Acondicionamiento Fisico | J34: =SUM(B34:I34) -> 0
A35: 2.3 HORAS EN PROYECCIÓN SOCIAL Y CAPACITACIÓN
A36: c. Total de horas proyección social y formación | B36: =SUM(B37:B39) -> 0 | C36: =SUM(C37:C39) -> 0 | D36: =SUM(D37:D39) -> 0 | E36: =SUM(E37:E39) -> 0 | F36: =SUM(F37:F39) -> 0 | G36: =SUM(G37:G39) -> 0 | H36: =SUM(H37:H39) -> 0 | I36: =SUM(I37:I39) -> 0 | J36: =SUM(B36:I36) -> 0
A37: c.1. Horas en charlas, talleres, capacitaciones impartidas | J37: =SUM(B37:I37) -> 0
A38: c.2. Horas en charlas, talleres, capacitaciones recibidas | J38: =SUM(B38:I38) -> 0
A39: c.3. Horas en actividades comunitarias | J39: =SUM(B39:I39) -> 0
A40: 2.4 OTRAS HORAS
A41: d.Total de Horas no operativas en servicio dentro de la base o puesto (stand by: espera por alerta de narcotráfico, espera por logística, espera por alguna situación ). | J41: =SUM(B41:I41) -> 0
...

Sheet Hoja1
B1: HOJAS
B2: ESTACIÓN | E2: CONTADOR
B3: SNG-08 | E3: =1+COUNTA(B2:B10) -> 10
B4: SNG-16
B5: SNG-25
B6: GC-38-11
B7: GC-38-22
B8: MEGAOP
B9: CAMINANDO
B10: APOYO
